<?xml version="1.0"?>
<robot xmlns:xacro="http://www.ros.org/wiki/xacro" name="wsg50">
    <!-- Materials -->
    <material name="wsg50_Gray">
      <color rgba="0.7 0.7 0.7 1.0"/>
    </material>
    <material name="wsg50_DarkGray">
      <color rgba="0.3 0.3 0.3 1.0"/>
    </material>

    <!-- Gripper Body -->
    <link name="wsg50_gripper_link">
      <visual>
        <origin xyz="0 0 0" rpy="0 0 0"/>
        <geometry>
          <mesh filename="package://wsg_description/meshes/wsg50_110.stl"
            scale="0.001 0.001 0.001"/>
        </geometry>
        <material name="wsg50_Gray"/>
      </visual> 
    </link> 

    <!-- Fingers -->
    <link name="wsg50_thumb_link">
      <visual>
        <origin xyz="0 0 0" rpy="0 0 0"/>
        <geometry>
          <mesh filename="package://wsg_description/meshes/wsg_f.stl"
            scale="0.001 0.001 0.001"/>
        </geometry>
        <material name="wsg50_DarkGray"/>
      </visual>
    </link>
    <link name="wsg50_index_link">
      <visual>
        <origin xyz="0 0 0" rpy="0 0 0"/>
        <geometry>
          <mesh filename="package://wsg_description/meshes/wsg_f.stl"
            scale="0.001 0.001 0.001"/>
        </geometry>
        <material name="wsg50_DarkGray"/>
      </visual>
    </link>

    <joint name="wsg50_thumb_joint" type="prismatic">
      <limit effort="1000.0" lower="0.0" upper="0.055" velocity="0.5"/>
      <parent link="wsg50_gripper_link"/>
      <child link="wsg50_thumb_link"/>
      <origin xyz="0 -0.096 0" rpy="3.141 0 0"/>
    </joint>

    <joint name="wsg50_index_joint" type="prismatic">
      <limit effort="1000.0" lower="0.0" upper="0.055" velocity="0.5"/>
      <parent link="wsg50_gripper_link"/>
      <child link="wsg50_index_link"/>
      <origin xyz="0 -0.096 0" rpy="3.141 3.141 0"/>
    </joint>


</robot>
